Workbook

Sheet 所需数据
A1: 员工号 | B1: 科室 | C1: 姓名 | D1: 总数 | E1: 处理最多的国家 | F1: 处理最多的数量 | G1: 三星以上 | H1: 邮件处理
A2: 182358 | B2: 航行情报室 | C2: 何萍 | D2: 230 | E2: 中国香港 | F2: 123 | G2: 24 | H2: 0
A3: 202984 | B3: 航行情报室 | C3: 刘洋 | D3: 364 | E3: 澳大利亚 | F3: 138 | G3: 53 | H3: 940
A4: 215456 | B4: 航行情报室 | C4: 刘云鹏 | D4: 268 | E4: 日本 | F4: 236 | G4: 25 | H4: 844
A5: 215448 | B5: 航行情报室 | C5: 欧阳嘉兰 | D5: 108 | E5: 日本 | F5: 86 | G5: 2 | H5: 215
A6: 240587 | B6: 航行情报室 | C6: 王康健 | D6: 2 | E6: 尼泊尔 | F6: 1 | G6: 0 | H6: 0
A7: 276401 | B7: 航行情报室 | C7: 王钰婷 | D7: 225 | E7: 比利时 | F7: 74 | G7: 21 | H7: 242
A8: 215462 | B8: 航行情报室 | C8: 吴坤林 | D8: 175 | E8: 泰国 | F8: 66 | G8: 14 | H8: 213
A9: 215454 | B9: 航行情报室 | C9: 吴奕铭 | D9: 302 | E9: 韩国 | F9: 137 | G9: 32 | H9: 303
A10: 252186 | B10: 航行情报室 | C10: 杨子城 | D10: 51 | E10: 韩国 | F10: 25 | G10: 0 | H10: 53
A11: 207803 | B11: 航行情报室 | C11: 袁伟英 | D11: 911 | E11: 法国 | F11: 232 | G11: 61 | H11: 2688
A12: 215443 | B12: 航行情报室 | C12: 张荷竞 | D12: 176 | E12: 印度 | F12: 92 | G12: 14 | H12: 606
A13: 606642 | B13: 航行情报室 | C13: 张宁 | D13: 94 | E13: 巴基斯坦 | F13: 24 | G13: 16 | H13: 62
A14: 215474 | B14: 航行情报室 | C14: 甄薇 | D14: 188 | E14: 波兰 | F14: 65 | G14: 11 | H14: 594

Sheet 统计总表
A1: 员工号 | B1: 姓名 | C1: 总数 | D1: 处理最多的国家 | E1: 处理最多的数量 | F1: 三星以上 | G1: 阿联酋 | H1: 阿塞拜疆 | I1: 爱沙尼亚 | J1: 奥地利 | K1: 澳大利亚 | L1: 巴基斯坦 | M1: 白俄罗斯 | N1: 比利时 | O1: 波兰 | P1: 丹麦 | Q1: 德国 | R1: 俄罗斯 | S1: 法国 | T1: 菲律宾 | U1: 芬兰 | V1: 格鲁吉亚 | W1: 哈萨克斯坦 | X1: 韩国 | Y1: 荷兰 | Z1: 吉尔吉斯斯坦 | AA1: 加拿大 | AB1: 柬埔寨 | AC1: 肯尼亚 | AD1: 拉脱维亚 | AE1: 老挝 | AF1: 立陶宛 | AG1: 马尔代夫 | AH1: 马来西亚 | AI1: 马里 | AJ1: 蒙古 | AK1: 孟加拉 | AL1: 缅甸 | AM1: 尼泊尔 | AN1: 日本 | AO1: 瑞典 | AP1: 斯里兰卡 | AQ1: 塔吉克斯坦 | AR1: 泰国 | AS1: 土耳其 | AT1: 乌兹别克斯坦 | AU1: 新加坡 | AV1: 新西兰 | AW1: 伊朗 | AX1: 意大利 | AY1: 印度 | AZ1: 印尼 | BA1: 英国 | BB1: 越南 | BC1: 中国澳门 | BD1: 中国台湾 | BE1: 中国香港
A2: 207803 | B2: 袁伟英 | C2: =COUNTIF(Sheet1!N:N,统计总表!B2) -> 911 | D2: =INDEX(G$1:BE$1,MATCH(E2,G2:BE2,0)) -> 法国 | E2: =MAX(G2:BE2) -> 232 | F2: 61 | G2: =COUNTIF(袁伟英!A:B,G1) -> 0 | H2: =COUNTIF(袁伟英!A:B,H1) -> 0 | I2: =COUNTIF(袁伟英!A:B,I1) -> 12 | J2: =COUNTIF(袁伟英!1:1048576,J1) -> 42 | K2: =COUNTIF(袁伟英!1:1048576,K1) -> 0 | L2: =COUNTIF(袁伟英!1:1048576,L1) -> 0 | M2: =COUNTIF(袁伟英!1:1048576,M1) -> 3 | N2: =COUNTIF(袁伟英!1:1048576,N1) -> 0 | O2: =COUNTIF(袁伟英!1:1048576,O1) -> 21 | P2: =COUNTIF(袁伟英!1:1048576,P1) -> 13 | Q2: =COUNTIF(袁伟英!1:1048576,Q1) -> 62 | ... BE2: =COUNTIF(袁伟英!1:1048576,BE1) -> 0
A3: 182358 | B3: 何萍 | C3: =COUNTIF(Sheet1!N:N,统计总表!B3) -> 230 | D3: =INDEX(G$1:BE$1,MATCH(E3,G3:BE3,0)) -> 中国香港 | E3: =MAX(G3:BE3) -> 123 | F3: 24 | G3: =COUNTIF(何萍!1:1048576,G1) -> 0 | H3: =COUNTIF(何萍!1:1048576,H1) -> 0 | I3: =COUNTIF(何萍!1:1048576,I1) -> 0 | J3: =COUNTIF(何萍!1:1048576,J1) -> 0 | K3: =COUNTIF(何萍!1:1048576,K1) -> 0 | L3: =COUNTIF(何萍!1:1048576,L1) -> 0 | M3: =COUNTIF(何萍!1:1048576,M1) -> 0 | N3: =COUNTIF(何萍!1:1048576,N1) -> 0 | ... BE3: =COUNTIF(何萍!1:1048576,BE1) -> 123
A4: 215456 | B4: 刘云鹏 | C4: =COUNTIF(Sheet1!N:N,统计总表!B4) -> 268 | D4: =INDEX(G$1:BE$1,MATCH(E4,G4:BE4,0)) -> 日本 | E4: =MAX(G4:BE4) -> 236 | F4: 25 | G4: =COUNTIF(刘云鹏!1:1048576,G1) -> 0 | H4: =COUNTIF(刘云鹏!1:1048576,H1) -> 0 | I4: =COUNTIF(刘云鹏!1:1048576,I1) -> 0 | J4: =COUNTIF(刘云鹏!1:1048576,J1) -> 0 | K4: =COUNTIF(刘云鹏!1:1048576,K1) -> 0 | L4: =COUNTIF(刘云鹏!1:1048576,L1) -> 0 | M4: =COUNTIF(刘云鹏!1:1048576,M1) -> 0 | N4: =COUNTIF(刘云鹏!1:1048576,N1) -> 0 | ... BE4: =COUNTIF(刘云鹏!1:1048576,BE1) -> 0
A5: 202984 | B5: 刘洋 | C5: =COUNTIF(Sheet1!N:N,统计总表!B5) -> 364 | D5: =INDEX(G$1:BE$1,MATCH(E5,G5:BE5,0)) -> 澳大利亚 | E5: =MAX(G5:BE5) -> 138 | F5: 53 | G5: =COUNTIF(刘洋!1:1048576,G1) -> 0 | H5: =COUNTIF(刘洋!1:1048576,H1) -> 4 | I5: =COUNTIF(刘洋!1:1048576,I1) -> 0 | J5: =COUNTIF(刘洋!1:1048576,J1) -> 0 | K5: =COUNTIF(刘洋!1:1048576,K1) -> 138 | L5: =COUNTIF(刘洋!1:1048576,L1) -> 0 | M5: =COUNTIF(刘洋!1:1048576,M1) -> 0 | N5: =COUNTIF(刘洋!1:1048576,N1) -> 0 | ... BE5: =COUNTIF(刘洋!1:1048576,BE1) -> 0
B6: 欧阳嘉兰 | C6: =COUNTIF(Sheet1!N:N,统计总表!B6) -> 108 | D6: =INDEX(G$1:BE$1,MATCH(E6,G6:BE6,0)) -> 日本 | E6: =MAX(G6:BE6) -> 86 | F6: 2 | G6: =COUNTIF(欧阳嘉兰!1:1048576,G1) -> 0 | H6: =COUNTIF(欧阳嘉兰!1:1048576,H1) -> 0 | I6: =COUNTIF(欧阳嘉兰!1:1048576,I1) -> 0 | J6: =COUNTIF(欧阳嘉兰!1:1048576,J1) -> 0 | K6: =COUNTIF(欧阳嘉兰!1:1048576,K1) -> 0 | L6: =COUNTIF(欧阳嘉兰!1:1048576,L1) -> 0 | M6: =COUNTIF(欧阳嘉兰!1:1048576,M1) -> 0 | N6: =COUNTIF(欧阳嘉兰!1:1048576,N1) -> 0 | ... BE6: =COUNTIF(欧阳嘉兰!1:1048576,BE1) -> 0
A7: 252186 | B7: 杨子城 | C7: =COUNTIF(Sheet1!N:N,统计总表!B7) -> 51 | D7: =INDEX(G$1:BE$1,MATCH(E7,G7:BE7,0)) -> 韩国 | E7: =MAX(G7:BE7) -> 25 | F7: 0 | G7: =COUNTIF(杨子城!1:1048576,G1) -> 20 | H7: =COUNTIF(杨子城!1:1048576,H1) -> 0 | I7: =COUNTIF(杨子城!1:1048576,I1) -> 0 | J7: =COUNTIF(杨子城!1:1048576,J1) -> 0 | K7: =COUNTIF(杨子城!1:1048576,K1) -> 0 | L7: =COUNTIF(杨子城!1:1048576,L1) -> 0 | M7: =COUNTIF(杨子城!1:1048576,M1) -> 0 | N7: =COUNTIF(杨子城!1:1048576,N1) -> 0 | ... BE7: =COUNTIF(杨子城!1:1048576,BE1) -> 0
A8: 276401 | B8: 王钰婷 | C8: =COUNTIF(Sheet1!N:N,统计总表!B8) -> 225 | D8: =INDEX(G$1:BE$1,MATCH(E8,G8:BE8,0)) -> 比利时 | E8: =MAX(G8:BE8) -> 74 | F8: 21 | G8: =COUNTIF(王钰婷!1:1048576,G1) -> 0 | H8: =COUNTIF(王钰婷!1:1048576,H1) -> 0 | I8: =COUNTIF(王钰婷!1:1048576,I1) -> 0 | J8: =COUNTIF(王钰婷!1:1048576,J1) -> 0 | K8: =COUNTIF(王钰婷!1:1048576,K1) -> 0 | L8: =COUNTIF(王钰婷!1:1048576,L1) -> 0 | M8: =COUNTIF(王钰婷!1:1048576,M1) -> 0 | N8: =COUNTIF(王钰婷!1:1048576,N1) -> 74 | ... BE8: =COUNTIF(王钰婷!1:1048576,BE1) -> 0
B9: 吴坤林 | C9: =COUNTIF(Sheet1!N:N,统计总表!B9) -> 175 | D9: =INDEX(G$1:BE$1,MATCH(E9,G9:BE9,0)) -> 泰国 | E9: =MAX(G9:BE9) -> 66 | F9: 14 | G9: =COUNTIF(吴坤林!1:1048576,G1) -> 0 | H9: =COUNTIF(吴坤林!1:1048576,H1) -> 0 | I9: =COUNTIF(吴坤林!1:1048576,I1) -> 0 | J9: =COUNTIF(吴坤林!1:1048576,J1) -> 0 | K9: =COUNTIF(吴坤林!1:1048576,K1) -> 0 | L9: =COUNTIF(吴坤林!1:1048576,L1) -> 0 | M9: =COUNTIF(吴坤林!1:1048576,M1) -> 0 | N9: =COUNTIF(吴坤林!1:1048576,N1) -> 0 | ... BE9: =COUNTIF(吴坤林!1:1048576,BE1) -> 0
B10: 吴奕铭 | C10: =COUNTIF(Sheet1!N:N,统计总表!B10) -> 302 | D10: =INDEX(G$1:BE$1,MATCH(E10,G10:BE10,0)) -> 韩国 | E10: =MAX(G10:BE10) -> 137 | F10: 32 | G10: =COUNTIF(吴奕铭!1:1048576,G1) -> 101 | H10: =COUNTIF(吴奕铭!1:1048576,H1) -> 0 | I10: =COUNTIF(吴奕铭!1:1048576,I1) -> 0 | J10: =COUNTIF(吴奕铭!1:1048576,J1) -> 0 | K10: =COUNTIF(吴奕铭!1:1048576,K1) -> 0 | L10: =COUNTIF(吴奕铭!1:1048576,L1) -> 0 | M10: =COUNTIF(吴奕铭!1:1048576,M1) -> 0 | N10: =COUNTIF(吴奕铭!1:1048576,N1) -> 0 | ... BE10: =COUNTIF(吴奕铭!1:1048576,BE1) -> 0
B11: 王康健 | C11: =COUNTIF(Sheet1!N:N,统计总表!B11) -> 2 | D11: =INDEX(G$1:BE$1,MATCH(E11,G11:BE11,0)) -> 尼泊尔 | E11: =MAX(G11:BE11) -> 1 | F11: 0 | G11: =COUNTIF(王康健!1:1048576,G1) -> 0 | H11: =COUNTIF(王康健!1:1048576,H1) -> 0 | I11: =COUNTIF(王康健!1:1048576,I1) -> 0 | J11: =COUNTIF(王康健!1:1048576,J1) -> 0 | K11: =COUNTIF(王康健!1:1048576,K1) -> 0 | L11: =COUNTIF(王康健!1:1048576,L1) -> 0 | M11: =COUNTIF(王康健!1:1048576,M1) -> 0 | N11: =COUNTIF(王康健!1:1048576,N1) -> 0 | ... BE11: =COUNTIF(王康健!1:1048576,BE1) -> 0
A12: 215443 | B12: 张荷竞 | C12: =COUNTIF(Sheet1!N:N,统计总表!B12) -> 176 | D12: =INDEX(G$1:BE$1,MATCH(E12,G12:BE12,0)) -> 印度 | E12: =MAX(G12:BE12) -> 92 | F12: 14 | G12: =COUNTIF(张荷竞!1:1048576,G1) -> 0 | H12: =COUNTIF(张荷竞!1:1048576,H1) -> 0 | I12: =COUNTIF(张荷竞!1:1048576,I1) -> 0 | J12: =COUNTIF(张荷竞!1:1048576,J1) -> 0 | K12: =COUNTIF(张荷竞!1:1048576,K1) -> 0 | L12: =COUNTIF(张荷竞!1:1048576,L1) -> 37 | M12: =COUNTIF(张荷竞!1:1048576,M1) -> 0 | N12: =COUNTIF(张荷竞!1:1048576,N1) -> 0 | ... BE12: =COUNTIF(张荷竞!1:1048576,BE1) -> 0
A13: 215474 | B13: 甄薇 | C13: =COUNTIF(Sheet1!N:N,统计总表!B13) -> 188 | D13: =INDEX(G$1:BE$1,MATCH(E13,G13:BE13,0)) -> 波兰 | E13: =MAX(G13:BE13) -> 65 | F13: 11 | G13: =COUNTIF(甄薇!1:1048576,G1) -> 0 | H13: =COUNTIF(甄薇!1:1048576,H1) -> 0 | I13: =COUNTIF(甄薇!1:1048576,I1) -> 9 | J13: =COUNTIF(甄薇!1:1048576,J1) -> 0 | K13: =COUNTIF(甄薇!1:1048576,K1) -> 0 | L13: =COUNTIF(甄薇!1:1048576,L1) -> 0 | M13: =COUNTIF(甄薇!1:1048576,M1) -> 4 | N13: =COUNTIF(甄薇!1:1048576,N1) -> 0 | ... BE13: =COUNTIF(甄薇!1:1048576,BE1) -> 0
A14: 606642 | B14: 张宁 | C14: =COUNTIF(Sheet1!N:N,统计总表!B14) -> 94 | D14: =INDEX(G$1:BE$1,MATCH(E14,G14:BE14,0)) -> 巴基斯坦 | E14: =MAX(G14:BE14) -> 24 | F14: 16 | G14: =COUNTIF(张宁!1:1048576,G1) -> 0 | H14: =COUNTIF(张宁!1:1048576,H1) -> 0 | I14: =COUNTIF(张宁!1:1048576,I1) -> 0 | J14: =COUNTIF(张宁!1:1048576,J1) -> 0 | K14: =COUNTIF(张宁!1:1048576,K1) -> 0 | L14: =COUNTIF(张宁!1:1048576,L1) -> 24 | M14: =COUNTIF(张宁!1:1048576,M1) -> 0 | N14: =COUNTIF(张宁!1:1048576,N1) -> 0 | ... BE14: =COUNTIF(张宁!1:1048576,BE1) -> 2
C15: =SUM(C2:C14) -> 3094 | G15: =SUM(G2:G14) -> 121 | H15: =SUM(H2:H14) -> 4 | I15: =SUM(I2:I14) -> 21 | J15: =SUM(J2:J14) -> 42 | K15: =SUM(K2:K14) -> 138 | L15: =SUM(L2:L14) -> 61 | M15: =SUM(M2:M14) -> 7 | N15: =SUM(N2:N14) -> 74 | ... BE15: =SUM(BE2:BE14) -> 125
G16: 三星以上
G17: =COUNTIF(三星以上!1:1048576,G1) -> 8 | H17: =COUNTIF(三星以上!1:1048576,H1) -> 0 | I17: =COUNTIF(三星以上!1:1048576,I1) -> 1 | J17: =COUNTIF(三星以上!1:1048576,J1) -> 3 | K17: =COUNTIF(三星以上!1:1048576,K1) -> 25 | L17: =COUNTIF(三星以上!1:1048576,L1) -> 4 | M17: =COUNTIF(三星以上!1:1048576,M1) -> 1 | N17: =COUNTIF(三星以上!1:1048576,N1) -> 5 | ... BE17: =COUNTIF(三星以上!1:1048576,BE1) -> 25

Sheet Sheet1
A1: id | B1: period | C1: countryName | D1: title | E1: modifiedParts | F1: type | G1: content | H1: deptIds | I1: dept | J1: effDt | K1: expDt | L1: analyzeResult | M1: createStaff | N1: staffName | O1: operatorName | P1: createTime | Q1: showPath | R1: flowStatus | S1: relatedFileid | T1: operTime | U1: sendEmail | V1: effDtType | W1: expDtType | X1: attention | Y1: airInfluence | Z1: flowInfoId
A2: 537 | B2: 202102 | C2: 法国 | D2: 修订BREST UAC高空管制区域的无线通信设备信息 | E2: AMDT A 02/21 GEN3.4-55 | F2: 19 | G2: 20210208d45b8e1d-b743-4331-8b6d-65dec621507b.txt | H2: 1,12,15,16,17 | I2: 飞行总队,运指航务,运指调度,运指签派 | J2: 2021-02-25 00:00 | K2: 2999-12-31 00:00 | L2: 请相关部门了解 | M2: 207803 | N2: 袁伟英 | O2: 袁伟英 | P2: 2021-02-08 14:28 | Q2: /全球AIP/欧洲/法国/AMDT | R2: Y | T2: 2021-02-09 13:17 | U2: N | Z2: 597
A3: 539 | B3: 202102 | C3: 法国 | D3: 修订管制区域的水平、垂直范围信息 | E3: AMDT A 02/21 ENR2.2-15 | F3: 19 | G3: 2021020832f75169-7b57-4396-8ff2-63ca1eec965d.txt | H3: 1,12 | I3: 飞行总队 | J3: 2021-02-25 00:00 | K3: 2999-12-31 00:00 | L3: 请相关部门了解 | M3: 207803 | N3: 袁伟英 | O3: 袁伟英 | P3: 2021-02-08 14:55 | Q3: /全球AIP/欧洲/法国/AMDT | R3: Y | T3: 2021-02-09 13:17 | U3: N | Z3: 599
A4: 549 | B4: 202102 | C4: 意大利 | D4: LIEO机场发布施工计划 | E4: SUP 01/21 | F4: 27 | G4: 20210209136f853c-13a6-46ec-aa9c-df854f721db9.txt | J4: 2021-03-25 00:00 | K4: 2021-07-14 00:00 | L4: 无影响 | M4: 207803 | N4: 袁伟英 | O4: 袁伟英 | P4: 2021-02-09 12:40 | Q4: /全球AIP/欧洲/意大利/SUP | R4: Y | S4: 458537 | T4: 2021-02-09 13:12 | U4: N | Z4: 609
A5: 550 | B5: 202102 | C5: 意大利 | D5: LICC机场发布施工计划 | E5: SUP 03/21 | F5: 27 | G5: 2021020922a9001b-648b-4aea-9e98-58b97a851d47.txt | J5: 2021-04-01 00:00 | K5: 2021-09-30 00:00 | L5: 无影响 | M5: 207803 | N5: 袁伟英 | O5: 袁伟英 | P5: 2021-02-09 12:43 | Q5: /全球AIP/欧洲/意大利/SUP | R5: Y | S5: 458539 | T5: 2021-02-09 13:12 | U5: N | Z5: 610
A6: 552 | B6: 202102 | C6: 法国 | D6: 在机场LFOJ建立实验性的无线电和应答机强制区域 | E6: SUP 14/21 | F6: 3 | G6: 20210209d80af11f-9e99-4b46-8008-c08f45008fbf.txt | J6: 2021-02-18 00:00 | K6: 2021-04-21 00:00 | L6: 无影响 | M6: 207803 | N6: 袁伟英 | O6: 袁伟英 | P6: 2021-02-09 12:58 | Q6: /全球AIP/欧洲/法国/SUP | R6: Y | S6: 458542 | T6: 2021-02-09 13:11 | U6: N | Z6: 612
A7: 553 | B7: 202102 | C7: 法国 | D7: 临时限制区的建立 | E7: SUP 15/21 | F7: 16 | G7: 202102098da7328b-4581-478a-94d9-96485848a794.txt | J7: 2021-02-22 00:00 | K7: 2021-02-26 00:00 | L7: 经系统检查，无影响 | M7: 207803 | N7: 袁伟英 | O7: 袁伟英 | P7: 2021-02-09 13:01 | Q7: /全球AIP/欧洲/法国/SUP | R7: Y | S7: 458543 | T7: 2021-02-09 13:11 | U7: N | Z7: 613
A8: 554 | B8: 202102 | C8: 印度 | D8: 关于通过数字天空平台在印度领空允许操作区域远程驾驶飞机的信息 | E8: SUP25/21 | F8: 10 | G8: 202102094b84eb22-f8db-4e56-9961-dc7123a4c011.txt | J8: 2021-02-05 00:00 | K8: 2999-12-31 00:00 | M8: 215443 | N8: 张荷竞 | O8: 袁伟英 | P8: 2021-02-09 14:29 | Q8: /全球AIP/亚洲/印度/SUP | R8: Y | S8: 458544 | T8: 2021-02-10 14:59 | U8: N | Z8: 614
A9: 556 | B9: 202102 | C9: 澳大利亚 | D9: YSTW机场地面灯光替换 | E9: AIC H05/21 | F9: 27 | G9: 2021020979bb8b05-cee7-450d-a5d0-f9dbeed8773d.txt | H9: 12 | J9: 2021-02-28 00:00 | K9: 2999-12-31 00:00 | L9: 暂无影响 | M9: 202984 | N9: 刘洋 | O9: 袁伟英 | P9: 2021-02-09 14:54 | Q9: /全球AIP/大洋洲/澳大利亚/AIC/2021 | R9: Y | S9: 458546 | T9: 2021-02-10 14:59 | U9: N | Z9: 616
A10: 557 | B10: 202102 | C10: 英国 | D10: EGPH机场区域新增障碍物信息 | E10: SUP 07/21 | F10: 24 | G10: 202102101c0b0f1d-be26-4e12-ad76-6a5062ffb4cd.txt | J10: 2021-02-11 00:00 | K10: 2021-09-01 00:00 | L10: 无影响 | M10: 207803 | N10: 袁伟英 | O10: 袁伟英 | P10: 2021-02-10 15:37 | Q10: /全球AIP/欧洲/英国/SUP | R10: Y | S10: 459663 | T10: 2021-02-10 15:58 | U10: N | Z10: 617
A11: 559 | B11: 202102 | C11: 英国 | D11: 英国SUP校核单 | E11: SUP 09/21 | F11: 6 | G11: 202102100df3b3d1-9471-4849-b763-0a13ff595f11.txt | J11: 2021-02-11 00:00 | K11: 2999-12-31 00:00 | L11: 英国SUP 校核单简单了解，暂无影响 | M11: 207803 | N11: 袁伟英 | O11: 袁伟英 | P11: 2021-02-10 16:01 | Q11: /全球AIP/欧洲/英国/SUP | R11: Y | S11: 459665 | T11: 2021-02-10 16:01 | U11: N | Z11: 619
A12: 560 | B12: 202102 | C12: 英国 | D12: 公布英国最新AIC校核单 | E12: AIC W004/21 | F12: 6 | G12: 20210210ea556e9d-1792-4ef6-ab3c-28138bb6e576.txt | J12: 2021-02-11 00:00 | K12: 2999-12-31 00:00 | L12: 暂无影响 | M12: 207803 | N12: 袁伟英 | O12: 袁伟英 | P12: 2021-02-10 16:06 | Q12: /全球AIP/欧洲/英国/AIC | R12: Y | S12: 459666 | T12: 2021-02-10 17:04 | U12: N | Z12: 620
A13: 561 | B13: 202102 | C13: 英国 | D13: 公布EGTH机场信息及2021年特殊事件 | E13: AIC Y002/21 | F13: 29 | G13: 2021021055765676-427c-4f83-8a10-67a11fb4a0b6.txt | J13: 2021-02-11 00:00 | K13: 2999-12-31 00:00 | L13: 非监控航点，无影响 | M13: 207803 | N13: 袁伟英 | O13: 袁伟英 | P13: 2021-02-10 16:13 | Q13: /全球AIP/欧洲/英国/AIC | R13: Y | S13: 459667 | T13: 2021-02-10 17:04 | U13: N | Z13: 621
A14: 562 | B14: 202102 | C14: 英国 | D14: 因军演对部分区域进行GPS信号干扰测试 | E14: AIC Y003/21 | F14: 19 | G14: 2021021071581298-04b7-4033-8d6b-0afb9d38a656.txt | J14: 2021-02-21 00:00 | K14: 2021-04-09 00:00 | L14: 暂无影响 | M14: 207803 | N14: 袁伟英 | O14: 袁伟英 | P14: 2021-02-10 16:52 | Q14: /全球AIP/欧洲/英国/AIC | R14: Y | S14: 459668 | T14: 2021-02-10 16:52 | U14: N | Z14: 622
A15: 564 | B15: 202102 | C15: 韩国 | D15: RKPU机场临时障碍物修正 | E15: AIP SUP 03/21 | F15: 24 | G15: 20210210feeec771-198a-4a81-b96d-e8093b00e810.txt | J15: 2020-12-31 00:00 | K15: 2021-05-31 15:00 | L15: 暂无影响 | M15: 207803 | N15: 袁伟英 | O15: 袁伟英 | P15: 2021-02-10 17:37 | Q15: /全球AIP/亚洲/韩国/AIC/2021 | R15: Y | S15: 459670 | T15: 2021-02-10 17:38 | U15: N | Z15: 624
A16: 567 | B16: 202102 | C16: 澳大利亚 | D16: YOLD机场修订RNAV(GNSS)07/25进近程序 | E16: SUP H25/21 | F16: 5,32 | G16: 20210211f0adeef0-2f57-438e-9992-e79e37b4ae0c.txt | H16: 12,17 | I16: 运指签派 | J16: 2021-02-20 02:00 | K16: 2999-12-31 00:00 | L16: 暂无影响 | M16: 202984 | N16: 刘洋 | O16: 袁伟英 | P16: 2021-02-11 18:26 | Q16: /全球AIP/大洋洲/澳大利亚/SUP/2021 | R16: Y | S16: 459673 | T16: 2021-02-16 10:18 | U16: N | Z16: 627
A17: 568 | B17: 202102 | C17: 澳大利亚 | D17: YOLD机场修订ERSA机场信息和RDS跑道长度 | E17: SUP H27/21 | F17: 4 | G17: 202102114e8ad1b9-63e0-48cb-b865-8e29596dc8e0.txt | H17: 12,17 | I17: 运指签派 | J17: 2021-02-20 02:00 | K17: 2999-12-31 00:00 | L17: 暂无影响 | M17: 202984 | N17: 刘洋 | O17: 袁伟英 | P17: 2021-02-11 19:41 | Q17: /全球AIP/大洋洲/澳大利亚/SUP/2021 | R17: Y | S17: 459674 | T17: 2021-02-16 10:18 | U17: N | Z17: 628
A18: 575 | B18: 202102 | C18: 日本 | D18: 福岛机场新增直升机程序 | E18: RJ SUP 002/21 | F18: 29 | G18: 20210212f4ce3373-e845-4630-be18-32023933e7d5.txt | J18: 2021-02-25 00:00 | K18: 2999-12-31 00:00 | L18: 对公司运行无影响。 | M18: 215456 | N18: 刘云鹏 | O18: 刘云鹏 | P18: 2021-02-12 16:42 | Q18: /全球AIP/亚洲/日本/SUP/2021 | R18: Y | S18: 459010 | T18: 2021-02-12 20:05 | U18: N | Z18: 635
A19: 578 | B19: 202102 | C19: 日本 | D19: 日本释放观测气球 | E19: RJ SUP 005/21 | F19: 29 | G19: 20210212591fb460-bb74-436d-8b0f-c611f3a97a65.txt | J19: 2021-02-25 00:00 | K19: 2999-12-31 00:00 | L19: 无影响。 | M19: 215456 | N19: 刘云鹏 | O19: 刘云鹏 | P19: 2021-02-12 19:02 | Q19: /全球AIP/亚洲/日本/SUP/2021 | R19: Y | S19: 459013 | T19: 2021-02-12 20:05 | U19: N | Z19: 638
A20: 579 | B20: 202102 | C20: 日本 | D20: 航空自卫队演习 | E20: RJ SUP 006/21 | F20: 16 | G20: 20210212aac97d45-422e-419e-8e24-f9ff865062cf.txt | J20: 2021-02-25 00:00 | K20: 2999-12-31 00:00 | M20: 215456 | N20: 刘云鹏 | O20: 刘云鹏 | P20: 2021-02-12 19:07 | Q20: /全球AIP/亚洲/日本/SUP/2021 | R20: Y | S20: 459014 | T20: 2021-02-12 20:05 | U20: N | Z20: 639
A21: 580 | B21: 202102 | C21: 日本 | D21: RJKA机场程序修订 | E21: RJ SUP 007/21 | F21: 21 | G21: 2021021260938359-a3fc-44b8-a852-025e285e8720.txt | J21: 2021-02-25 00:00 | K21: 2999-12-31 00:00 | L21: 非南航航点，暂无影响 | M21: 215456 | N21: 刘云鹏 | O21: 刘云鹏 | P21: 2021-02-12 19:13 | Q21: /全球AIP/亚洲/日本/SUP/2021 | R21: Y | S21: 459015 | T21: 2021-02-12 20:05 | U21: N | Z21: 640
A22: 581 | B22: 202102 | C22: 日本 | D22: 日本松山机场新增运行限制 | E22: RJ SUP 008/21 | F22: 26 | G22: 20210212e2125ced-0356-4af7-b22f-32b4cb97649a.txt | J22: 2021-02-25 00:00 | K22: 2999-12-31 00:00 | L22: 非南航航点，无影响。 | M22: 215456 | N22: 刘云鹏 | O22: 刘云鹏 | P22: 2021-02-12 19:16 | Q22: /全球AIP/亚洲/日本/SUP/2021 | R22: Y | S22: 459016 | T22: 2021-02-12 20:05 | U22: N | Z22: 641
A23: 583 | B23: 202102 | C23: 日本 | D23: 福冈机场障碍物信息更新 | E23: RJ SUP 010/21 | F23: 24 | G23: 20210212528615a2-6a16-4e50-976e-fb57dcace719.txt | J23: 2021-02-25 00:00 | K23: 2999-12-31 00:00 | L23: 请性能评估，请飞行机组注意。 | M23: 215456 | N23: 刘云鹏 | O23: 刘云鹏 | P23: 2021-02-12 19:26 | Q23: /全球AIP/亚洲/日本/SUP/2021 | R23: Y | S23: 459018 | T23: 2021-02-12 20:05 | U23: N | Z23: 643
A24: 586 | B24: 202102 | C24: 法国 | D24: 法国颁布本国领土以外的飞越易冲突地区 | E24: AIC A 02/21 | F24: 7,10 | G24: 20210216fef975ad-d7c4-425a-8b92-471ebb78811f.txt | H24: 1,12,16,17 | I24: 飞行总队,运指调度,运指签派 | J24: 2021-02-11 00:00 | K24: 2999-12-31 00:00 | L24: 属南航运行区域，法国当局的规定，简单了解 | M24: 207803 | N24: 袁伟英 | O24: 袁伟英 | P24: 2021-02-16 10:49 | Q24: /全球AIP/欧洲/法国/AIC | R24: Y | S24: 459677 | T24: 2021-02-16 14:28 | U24: N | Z24: 646
A25: 587 | B25: 202102 | C25: 法国 | D25: 划设16个限制区供无人机飞行 | E25: SUP 16/21 | F25: 16 | G25: 2021021668004491-168f-4c12-8c51-e9db1dbc3d7a.txt | J25: 2021-02-25 00:00 | K25: 2021-08-18 00:00 | L25: 经检查，无影响 | M25: 207803 | N25: 袁伟英 | O25: 袁伟英 | P25: 2021-02-16 11:08 | Q25: /全球AIP/欧洲/法国/SUP | R25: Y | S25: 459678 | T25: 2021-02-16 14:28 | U25: N | Z25: 647
A26: 588 | B26: 202102 | C26: 法国 | D26: 评估Alsace 平原各医院间的直升机IFR航路 | E26: SUP 017/21 | F26: 15 | G26: 202102163d2b8341-accf-4e69-ba00-fe21d7190bed.txt | J26: 2021-03-25 00:00 | K26: 2021-04-22 00:00 | L26: 暂无影响 | M26: 207803 | N26: 袁伟英 | O26: 袁伟英 | P26: 2021-02-16 11:12 | Q26: /全球AIP/欧洲/法国/SUP | R26: Y | S26: 459679 | T26: 2021-02-16 14:28 | U26: N | Z26: 648
A27: 590 | B27: 202102 | C27: 法国 | D27: 建立危险区D300对应的飞行计划缓冲区 | E27: SUP A 19/21 | F27: 16 | G27: 2021021648f79303-3d39-41e9-bcd0-d6b882e3373a.txt | J27: 2021-03-26 00:00 | K27: 2021-12-01 00:00 | L27: 无影响 | M27: 207803 | N27: 袁伟英 | O27: 袁伟英 | P27: 2021-02-16 11:41 | Q27: /全球AIP/欧洲/法国/SUP | R27: Y | S27: 459681 | T27: 2021-02-16 14:27 | U27: N | Z27: 650
A28: 591 | B28: 202102 | C28: 法国 | D28: 关于直升飞机运行RNP261 Pins IFR程序的运行评估 | E28: SUP 20/21 | F28: 6 | G28: 20210216db3db394-6d0e-487e-a8b9-b3df96256fc1.txt | J28: 2021-03-25 00:00 | K28: 2021-04-20 00:00 | L28: 暂无影响 | M28: 207803 | N28: 袁伟英 | O28: 袁伟英 | P28: 2021-02-16 11:45 | Q28: /全球AIP/欧洲/法国/SUP | R28: Y | S28: 459682 | T28: 2021-02-16 14:27 | U28: N | Z28: 651
A29: 593 | B29: 202102 | C29: 法国 | D29: 因BELOTE 2021-02军演建立临时限制区危险区 | E29: SUP 22/21 | F29: 17 | G29: 202102161594aaa3-4f14-49db-9934-bec565453883.txt | J29: 2021-03-02 00:00 | K29: 2021-03-04 00:00 | L29: 无影响 | M29: 207803 | N29: 袁伟英 | O29: 袁伟英 | P29: 2021-02-16 12:04 | Q29: /全球AIP/欧洲/法国/SUP | R29: Y | S29: 459684 | T29: 2021-02-16 14:26 | U29: N | Z29: 653
A30: 595 | B30: 202102 | C30: 法国 | D30: 建立临时限制区 | E30: SUP 024/21 | F30: 16 | G30: 20210216c41ea0ad-0509-4d46-855f-2d31fa5601bb.txt | J30: 2021-03-01 00:00 | K30: 2021-08-13 00:00 | L30: 无影响 | M30: 207803 | N30: 袁伟英 | O30: 袁伟英 | P30: 2021-02-16 12:19 | Q30: /全球AIP/欧洲/法国/SUP | R30: Y | S30: 459686 | T30: 2021-02-16 14:25 | U30: N | Z30: 655
A31: 596 | B31: 202102 | C31: 芬兰 | D31: 芬兰建立临时限制区 | E31: SUP 06/21 | F31: 16 | G31: 2021021615fec0e0-4b7e-4d70-b345-3d75eb414201.txt | J31: 2021-02-23 07:00 | K31: 2021-02-25 14:30 | L31: 已检查，暂无影响 | M31: 207803 | N31: 袁伟英 | O31: 袁伟英 | P31: 2021-02-16 14:15 | Q31: /全球AIP/欧洲/芬兰/SUP | R31: Y | S31: 459689 | T31: 2021-02-16 14:25 | U31: N | Z31: 656
A32: 597 | B32: 202102 | C32: 芬兰 | D32: 芬兰建立临时危险区 | E32: SUP 07/21 | F32: 16 | G32: 20210216b571527a-30b5-4bac-af94-f0f280a35739.txt | J32: 2021-02-26 10:00 | K32: 2021-02-28 18:00 | L32: 芬兰属公司航路飞越地区，低高度限制区，暂无影响 | M32: 207803 | N32: 袁伟英 | O32: 袁伟英 | P32: 2021-02-16 14:25 | Q32: /全球AIP/欧洲/芬兰/SUP | R32: Y | S32: 459690 | T32: 2021-02-16 14:25 | U32: N | Z32: 657
A33: 598 | B33: 202102 | C33: 澳大利亚 | D33: YIBO机场新增进近程序 | E33: AIRAC SUP H29/21 | F33: 5,32 | G33: 202102173e925f20-f919-4541-a3c1-d620c3590b4c.txt | H33: 12 | J33: 2021-04-21 00:00 | K33: 2999-12-31 00:00 | L33: 暂无影响 | M33: 202984 | N33: 刘洋 | O33: 袁伟英 | P33: 2021-02-17 10:28 | Q33: /全球AIP/大洋洲/澳大利亚/SUP/2021 | R33: Y | S33: 459691 | T33: 2021-02-18 09:23 | U33: N | Z33: 658
A34: 599 | B34: 202102 | C34: 澳大利亚 | D34: YWLM机场在管制空域以下目视进近意外下降风险 | E34: AIC H06/21 | F34: 26 | G34: 2021021703f0a9ff-b75e-4f4b-9042-6b900c702cde.txt | H34: 12 | J34: 2021-02-16 00:00 | K34: 2022-03-01 10:53 | L34: 暂无影响 | M34: 202984 | N34: 刘洋 | O34: 袁伟英 | P34: 2021-02-17 10:54 | Q34: /全球AIP/大洋洲/澳大利亚/AIC/2021 | R34: Y | S34: 459692 | T34: 2021-02-18 09:23 | U34: N | Z34: 659
A35: 601 | B35: 202102 | C35: 越南 | D35: 越南VVDN岘港机场修改跑道相关参数、障碍物信息等 | E35: AIP SUP A06/21 | F35: 20,24,29 | G35: 2021022005b95636-130d-4a6c-b912-17aa9209b9c8.txt | H35: 1,12,14,17 | I35: 飞行总队,运指性能,运指签派 | J35: 2021-03-25 00:00 | K35: 2999-12-31 00:00 | L35: 对运行有影响，相关部门需要关注。 | M35: 215462 | N35: 吴坤林 | O35: 袁伟英 | P35: 2021-02-18 09:31 | Q35: /全球AIP/亚洲/越南/SUP | R35: Y | S35: 459707 | T35: 2021-02-27 10:29 | U35: N | Z35: 661
A36: 602 | B36: 202102 | C36: 印度 | D36: AIC校核单 | E36: AIC01/21 | F36: 6 | G36: 20210218775c8155-0795-45ff-b57d-5b77f8c7d5cc.txt | H36: 12 | J36: 2021-01-08 00:00 | K36: 2999-12-31 00:00 | M36: 215443 | N36: 张荷竞 | O36: 袁伟英 | P36: 2021-02-18 09:38 | Q36: /全球AIP/亚洲/印度/AIC | R36: Y | S36: 459712 | T36: 2021-02-20 16:44 | U36: N | Z36: 662
A37: 603 | B37: 202102 | C37: 中国台湾 | D37: RCTP机场修订滑行道道面及强度 | E37: 台湾AIP AMDT02/21(AD 2 RCTP-3、4) | F37: 22,29 | G37: 2021021897820687-98d8-457d-ba77-595db603ece9.txt | H37: 1,12,17 | I37: 飞行总队,运指签派 | J37: 2021-03-11 00:00 | K37: 2999-12-31 00:00 | L37: 对地面运行有影响，请相关部门注意 | M37: 182358 | N37: 何萍 | O37: 袁伟英 | P37: 2021-02-18 09:48 | Q37: /全球AIP/亚洲/中国台湾/AMDT | R37: Y | S37: 459711 | T37: 2021-02-20 16:49 | U37: N | Z37: 663
A38: 604 | B38: 202102 | C38: 印度 | D38: VIDP第三次管制期航空关税事宜 | E38: AIC06/21 | F38: 1 | G38: 202102186a16c53d-946a-4820-9ce2-c199b5ab2901.txt | H38: 12 | J38: 2021-01-12 00:00 | K38: 2999-12-31 00:00 | M38: 215443 | N38: 张荷竞 | O38: 袁伟英 | P38: 2021-02-18 09:50 | Q38: /全球AIP/亚洲/印度/AIC | R38: Y | S38: 459713 | T38: 2021-02-20 16:44 | U38: N | Z38: 664
A39: 605 | B39: 202102 | C39: 印度 | D39: VOTV机场停机位及滑行路线试运行 | E39: SUP 26/21 | F39: 23 | G39: 202102185c0f33fa-ff45-48cc-8d2a-65c710d04be9.txt | J39: 2021-02-05 00:00 | K39: 2999-12-31 00:00 | M39: 215443 | N39: 张荷竞 | O39: 袁伟英 | P39: 2021-02-18 09:57 | Q39: /全球AIP/亚洲/印度/SUP | R39: Y | S39: 459714 | T39: 2021-02-20 16:44 | U39: N | Z39: 665
A40: 607 | B40: 202102 | C40: 印度 | D40: VOHY机场数据 | E40: SUP 27/21 | F40: 4 | G40: 202102185b8b1b25-c8d6-465d-9f7c-1475b8b239d9.txt | J40: 2021-02-05 00:00 | K40: 2999-12-31 00:00 | M40: 215443 | N40: 张荷竞 | O40: 袁伟英 | P40: 2021-02-18 10:01 | Q40: /全球AIP/亚洲/印度/SUP | R40: Y | S40: 459715 | T40: 2021-02-20 16:42 | U40: N | Z40: 667
...

Sheet 三星以上
A1: countryName | B1: staffName | D1: 计数项:countryName
A2: 土耳其 | B2: 刘洋 | D2: staffName | E2: 汇总
A3: 印度 | B3: 张荷竞 | D3: 何萍 | E3: 24
A4: 中国香港 | B4: 何萍 | D4: 刘洋 | E4: 53
A5: 中国香港 | B5: 何萍 | D5: 刘云鹏 | E5: 25
A6: 中国香港 | B6: 张宁 | D6: 欧阳嘉兰 | E6: 2
A7: 越南 | B7: 张宁 | D7: 王钰婷 | E7: 21
A8: 马来西亚 | B8: 张荷竞 | D8: 王志铿 | E8: 1
A9: 英国 | B9: 袁伟英 | D9: 吴坤林 | E9: 14
A10: 俄罗斯 | B10: 刘洋 | D10: 吴奕铭 | E10: 32
A11: 英国 | B11: 袁伟英 | D11: 袁伟英 | E11: 61
A12: 荷兰 | B12: 袁伟英 | D12: 张荷竞 | E12: 14
A13: 拉脱维亚 | B13: 甄薇 | D13: 张宁 | E13: 16
A14: 阿联酋 | B14: 吴奕铭 | D14: 甄薇 | E14: 11
A15: 俄罗斯 | B15: 刘洋 | D15: 总计 | E15: 274
A16: 阿联酋 | B16: 吴奕铭
A17: 德国 | B17: 袁伟英
A18: 格鲁吉亚 | B18: 刘洋
A19: 格鲁吉亚 | B19: 刘洋
A20: 土耳其 | B20: 刘洋
A21: 土耳其 | B21: 刘洋
A22: 马尔代夫 | B22: 张荷竞
A23: 马尔代夫 | B23: 张荷竞
A24: 澳大利亚 | B24: 刘洋
A25: 格鲁吉亚 | B25: 刘洋
A26: 格鲁吉亚 | B26: 刘洋
A27: 中国香港 | B27: 何萍
... A275: 柬埔寨 | B275: 刘云鹏

Sheet 张宁
A1: countryName | B1: staffName
A2: 法国 | B2: 张宁
A3: 法国 | B3: 张宁
A4: 巴基斯坦 | B4: 张宁
A5: 巴基斯坦 | B5: 张宁
A6: 尼泊尔 | B6: 张宁
A7: 巴基斯坦 | B7: 张宁
A8: 马来西亚 | B8: 张宁
A9: 肯尼亚 | B9: 张宁
A10: 肯尼亚 | B10: 张宁
A11: 巴基斯坦 | B11: 张宁
A12: 巴基斯坦 | B12: 张宁
... A95: 孟加拉 | B95: 张宁

Sheet 甄薇
A1: countryName | B1: staffName
A2: 拉脱维亚 | B2: 甄薇
A3: 拉脱维亚 | B3: 甄薇
A4: 拉脱维亚 | B4: 甄薇
A5: 波兰 | B5: 甄薇
A6: 波兰 | B6: 甄薇
A7: 波兰 | B7: 甄薇
A8: 波兰 | B8: 甄薇
A9: 丹麦 | B9: 甄薇
A10: 波兰 | B10: 甄薇
A11: 波兰 | B11: 甄薇
A12: 瑞典 | B12: 甄薇
... A189: 白俄罗斯 | B189: 甄薇

Sheet 张荷竞
A1: countryName | B1: staffName
A2: 印度 | B2: 张荷竞
A3: 印度 | B3: 张荷竞
A4: 印度 | B4: 张荷竞
A5: 印度 | B5: 张荷竞
A6: 印度 | B6: 张荷竞
A7: 印度 | B7: 张荷竞
A8: 印度 | B8: 张荷竞
A9: 印度 | B9: 张荷竞
A10: 印度 | B10: 张荷竞
A11: 印度 | B11: 张荷竞
A12: 印度 | B12: 张荷竞
... A127: 马尔代夫 | B127: 张荷竞
B128: 张荷竞
B129: 张荷竞
B130: 张荷竞
B131: 张荷竞
B132: 张荷竞
B133: 张荷竞
B134: 张荷竞
A135: 巴基斯坦 | B135: 张荷竞
A136: 巴基斯坦 | B136: 张荷竞
A137: 巴基斯坦 | B137: 张荷竞
A138: 巴基斯坦 | B138: 张荷竞
A139: 印度 | B139: 张荷竞
A140: 马来西亚 | B140: 张荷竞
A141: 印度 | B141: 张荷竞
A142: 马来西亚 | B142: 张荷竞
A143: 马尔代夫 | B143: 张荷竞
A144: 马尔代夫 | B144: 张荷竞
A145: 马来西亚 | B145: 张荷竞
A146: 马来西亚 | B146: 张荷竞
... A177: 马来西亚 | B177: 张荷竞

Sheet 王康健
A1: countryName | B1: staffName
B2: 王康健
A3: 尼泊尔 | B3: 王康健

Sheet 王钰婷
A1: countryName | B1: staffName
A2: 比利时 | B2: 王钰婷
A3: 比利时 | B3: 王钰婷
A4: 比利时 | B4: 王钰婷
A5: 比利时 | B5: 王钰婷
A6: 比利时 | B6: 王钰婷
A7: 比利时 | B7: 王钰婷
A8: 比利时 | B8: 王钰婷
A9: 比利时 | B9: 王钰婷
A10: 比利时 | B10: 王钰婷
A11: 比利时 | B11: 王钰婷
A12: 比利时 | B12: 王钰婷
... A226: 泰国 | B226: 王钰婷

Sheet 吴坤林
A1: countryName | B1: staffName
A2: 越南 | B2: 吴坤林
A3: 越南 | B3: 吴坤林
A4: 印尼 | B4: 吴坤林
A5: 印尼 | B5: 吴坤林
A6: 印尼 | B6: 吴坤林
A7: 泰国 | B7: 吴坤林
A8: 泰国 | B8: 吴坤林
A9: 泰国 | B9: 吴坤林
A10: 泰国 | B10: 吴坤林
A11: 泰国 | B11: 吴坤林
A12: 泰国 | B12: 吴坤林
... A19: 印尼 | B19: 吴坤林
B20: 吴坤林
B21: 吴坤林
B22: 吴坤林
A23: 越南 | B23: 吴坤林
A24: 泰国 | B24: 吴坤林
A25: 越南 | B25: 吴坤林
A26: 泰国 | B26: 吴坤林
A27: 印尼 | B27: 吴坤林
A28: 印尼 | B28: 吴坤林
A29: 印尼 | B29: 吴坤林
A30: 印尼 | B30: 吴坤林
A31: 印尼 | B31: 吴坤林
A32: 印尼 | B32: 吴坤林
A33: 印尼 | B33: 吴坤林
A34: 印尼 | B34: 吴坤林
... A65: 越南 | B65: 吴坤林
B66: 吴坤林
B67: 吴坤林
B68: 吴坤林
B69: 吴坤林
B70: 吴坤林
B71: 吴坤林
B72: 吴坤林
B73: 吴坤林
B74: 吴坤林
B75: 吴坤林
B76: 吴坤林
...

Sheet 吴奕铭
A1: countryName | B1: staffName
A2: 阿联酋 | B2: 吴奕铭
A3: 阿联酋 | B3: 吴奕铭
A4: 阿联酋 | B4: 吴奕铭
A5: 阿联酋 | B5: 吴奕铭
A6: 菲律宾 | B6: 吴奕铭
A7: 菲律宾 | B7: 吴奕铭
A8: 菲律宾 | B8: 吴奕铭
A9: 菲律宾 | B9: 吴奕铭
A10: 菲律宾 | B10: 吴奕铭
A11: 菲律宾 | B11: 吴奕铭
A12: 菲律宾 | B12: 吴奕铭
... A86: 阿联酋 | B86: 吴奕铭
B87: 吴奕铭
B88: 吴奕铭
B89: 吴奕铭
B90: 吴奕铭
B91: 吴奕铭
B92: 吴奕铭
B93: 吴奕铭
B94: 吴奕铭
B95: 吴奕铭
B96: 吴奕铭
B97: 吴奕铭
B98: 吴奕铭
... B113: 吴奕铭
A114: 韩国 | B114: 吴奕铭
A115: 韩国 | B115: 吴奕铭
A116: 韩国 | B116: 吴奕铭
A117: 韩国 | B117: 吴奕铭
A118: 韩国 | B118: 吴奕铭
A119: 韩国 | B119: 吴奕铭
A120: 韩国 | B120: 吴奕铭
A121: 韩国 | B121: 吴奕铭
A122: 韩国 | B122: 吴奕铭
A123: 韩国 | B123: 吴奕铭
A124: 韩国 | B124: 吴奕铭
A125: 韩国 | B125: 吴奕铭
... A303: 阿联酋 | B303: 吴奕铭

Sheet 杨子城
A1: countryName | B1: staffName
A2: 菲律宾 | B2: 杨子城
A3: 菲律宾 | B3: 杨子城
A4: 菲律宾 | B4: 杨子城
A5: 韩国 | B5: 杨子城
A6: 韩国 | B6: 杨子城
A7: 韩国 | B7: 杨子城
A8: 韩国 | B8: 杨子城
A9: 韩国 | B9: 杨子城
A10: 韩国 | B10: 杨子城
A11: 阿联酋 | B11: 杨子城
A12: 阿联酋 | B12: 杨子城
... A52: 韩国 | B52: 杨子城

Sheet 刘云鹏
A1: countryName | B1: staffName
A2: 日本 | B2: 刘云鹏
A3: 日本 | B3: 刘云鹏
A4: 日本 | B4: 刘云鹏
A5: 日本 | B5: 刘云鹏
A6: 日本 | B6: 刘云鹏
A7: 日本 | B7: 刘云鹏
A8: 日本 | B8: 刘云鹏
A9: 日本 | B9: 刘云鹏
A10: 日本 | B10: 刘云鹏 | G10: 柬埔寨 | H10: 老挝 | I10: 缅甸 | J10: 日本 | K10: 印度
A11: 日本 | B11: 刘云鹏 | G11: 3 | H11: 2 | I11: 2 | J11: 235 | K11: 18
A12: 日本 | B12: 刘云鹏
A13: 日本 | B13: 刘云鹏
A14: 日本 | B14: 刘云鹏
A15: 日本 | B15: 刘云鹏
A16: 日本 | B16: 刘云鹏
A17: 日本 | B17: 刘云鹏
A18: 日本 | B18: 刘云鹏
A19: 日本 | B19: 刘云鹏
A20: 日本 | B20: 刘云鹏
A21: 日本 | B21: 刘云鹏
A22: 日本 | B22: 刘云鹏
A23: 日本 | B23: 刘云鹏
... A142: 印度 | B142: 刘云鹏
B143: 刘云鹏
A144: 日本 | B144: 刘云鹏
B145: 刘云鹏
B146: 刘云鹏
B147: 刘云鹏
B148: 刘云鹏
B149: 刘云鹏
B150: 刘云鹏
B151: 刘云鹏
A152: 日本 | B152: 刘云鹏
A153: 日本 | B153: 刘云鹏
A154: 日本 | B154: 刘云鹏
A155: 日本 | B155: 刘云鹏
A156: 日本 | B156: 刘云鹏
A157: 日本 | B157: 刘云鹏
A158: 日本 | B158: 刘云鹏
...

Sheet 刘洋
A1: countryName | B1: staffName
A2: 澳大利亚 | B2: 刘洋
A3: 澳大利亚 | B3: 刘洋
A4: 澳大利亚 | B4: 刘洋
A5: 澳大利亚 | B5: 刘洋
A6: 澳大利亚 | B6: 刘洋
A7: 澳大利亚 | B7: 刘洋
A8: 澳大利亚 | B8: 刘洋
A9: 澳大利亚 | B9: 刘洋
A10: 澳大利亚 | B10: 刘洋
A11: 澳大利亚 | B11: 刘洋
A12: 澳大利亚 | B12: 刘洋
... A139: 新西兰 | B139: 刘洋
B140: 刘洋
B141: 刘洋
B142: 刘洋
B143: 刘洋
B144: 刘洋
B145: 刘洋
B146: 刘洋
B147: 刘洋
B148: 刘洋
B149: 刘洋
B150: 刘洋
B151: 刘洋
... B167: 刘洋
A168: 俄罗斯 | B168: 刘洋
A169: 俄罗斯 | B169: 刘洋
A170: 俄罗斯 | B170: 刘洋
A171: 俄罗斯 | B171: 刘洋
A172: 俄罗斯 | B172: 刘洋
A173: 澳大利亚 | B173: 刘洋
A174: 澳大利亚 | B174: 刘洋
A175: 俄罗斯 | B175: 刘洋
A176: 澳大利亚 | B176: 刘洋
A177: 澳大利亚 | B177: 刘洋
A178: 俄罗斯 | B178: 刘洋
A179: 哈萨克斯坦 | B179: 刘洋
... A365: 俄罗斯 | B365: 刘洋

Sheet 袁伟英
A1: countryName | B1: staffName
A2: 法国 | B2: 袁伟英
A3: 法国 | B3: 袁伟英
A4: 意大利 | B4: 袁伟英
A5: 意大利 | B5: 袁伟英
A6: 法国 | B6: 袁伟英
A7: 法国 | B7: 袁伟英
A8: 英国 | B8: 袁伟英
A9: 英国 | B9: 袁伟英
A10: 英国 | B10: 袁伟英
A11: 英国 | B11: 袁伟英
A12: 英国 | B12: 袁伟英
... A357: 芬兰 | B357: 袁伟英
A358: 丹麦 | B358: 袁伟英 | L358: 爱沙尼亚 | M358: 奥地利 | N358: 波兰 | O358: 丹麦 | P358: 德国 | Q358: 法国 | R358: 芬兰 | S358: 荷兰 | T358: 加拿大 | U358: 拉脱维亚 | V358: 立陶宛 | W358: 瑞典 | X358: 意大利 | Y358: 英国
A359: 瑞典 | B359: 袁伟英 | L359: 12 | M359: 41 | N359: 20 | O359: 12 | P359: 61 | Q359: 231 | R359: 99 | S359: 37 | T359: 92 | U359: 13 | V359: 11 | W359: 40 | X359: 46 | Y359: 144
A360: 瑞典 | B360: 袁伟英
A361: 意大利 | B361: 袁伟英
A362: 丹麦 | B362: 袁伟英
A363: 英国 | B363: 袁伟英
A364: 英国 | B364: 袁伟英
A365: 英国 | B365: 袁伟英
A366: 英国 | B366: 袁伟英
A367: 英国 | B367: 袁伟英
A368: 英国 | B368: 袁伟英
A369: 英国 | B369: 袁伟英
A370: 法国 | B370: 袁伟英
A371: 法国 | B371: 袁伟英
... A587: 波兰 | B587: 袁伟英
B588: 袁伟英
B589: 袁伟英
B590: 袁伟英
B591: 袁伟英
B592: 袁伟英
B593: 袁伟英
B594: 袁伟英
B595: 袁伟英
B596: 袁伟英
B597: 袁伟英
B598: 袁伟英
B599: 袁伟英
...

Sheet 欧阳嘉兰
A1: countryName | B1: staffName
A2: 印度 | B2: 欧阳嘉兰
A3: 日本 | B3: 欧阳嘉兰
A4: 日本 | B4: 欧阳嘉兰
A5: 日本 | B5: 欧阳嘉兰
A6: 日本 | B6: 欧阳嘉兰
A7: 日本 | B7: 欧阳嘉兰
A8: 日本 | B8: 欧阳嘉兰
A9: 日本 | B9: 欧阳嘉兰
A10: 日本 | B10: 欧阳嘉兰
A11: 日本 | B11: 欧阳嘉兰
A12: 印度 | B12: 欧阳嘉兰
... A109: 印度 | B109: 欧阳嘉兰

Sheet 何萍
A1: countryName | B1: staffName
A2: 中国台湾 | B2: 何萍
A3: 中国台湾 | B3: 何萍
A4: 中国台湾 | B4: 何萍
A5: 中国台湾 | B5: 何萍
A6: 中国台湾 | B6: 何萍
A7: 中国台湾 | B7: 何萍
A8: 中国香港 | B8: 何萍
A9: 中国香港 | B9: 何萍 | K9: 中国澳门 | L9: 中国台湾 | M9: 中国香港
A10: 中国香港 | B10: 何萍 | K10: 26 | L10: 62 | M10: 122
A11: 中国香港 | B11: 何萍
A12: 中国香港 | B12: 何萍
A13: 中国香港 | B13: 何萍
A14: 中国澳门 | B14: 何萍
A15: 中国台湾 | B15: 何萍
A16: 中国香港 | B16: 何萍
A17: 中国香港 | B17: 何萍
A18: 中国台湾 | B18: 何萍
A19: 中国香港 | B19: 何萍
A20: 中国香港 | B20: 何萍
A21: 中国香港 | B21: 何萍
A22: 中国澳门 | B22: 何萍
... A95: 中国台湾 | B95: 何萍
B96: 何萍
B97: 何萍
B98: 何萍
B99: 何萍
B100: 何萍
B101: 何萍
B102: 何萍
B103: 何萍
B104: 何萍
B105: 何萍
B106: 何萍
B107: 何萍
... B115: 何萍
A116: 中国澳门 | B116: 何萍
A117: 中国澳门 | B117: 何萍
A118: 中国澳门 | B118: 何萍
A119: 中国台湾 | B119: 何萍
...

Sheet Sheet21
A1: 阿联酋 | B1: 爱沙尼亚 | C1: 奥地利 | D1: 澳大利亚 | E1: 巴基斯坦 | F1: 白俄罗斯 | G1: 比利时 | H1: 波兰 | I1: 丹麦 | J1: 德国 | K1: 俄罗斯 | L1: 法国 | M1: 菲律宾 | N1: 芬兰 | O1: 格鲁吉亚 | P1: 哈萨克斯坦 | Q1: 韩国 | R1: 荷兰 | S1: 加拿大 | T1: 柬埔寨 | U1: 肯尼亚 | V1: 拉脱维亚 | W1: 马尔代夫 | X1: 马来西亚 | Y1: 蒙古 | Z1: 孟加拉 | AA1: 尼泊尔 | AB1: 日本 | AC1: 瑞典 | AD1: 泰国 | AE1: 土耳其 | AF1: 乌兹别克斯坦 | AG1: 新加坡 | AH1: 新西兰 | AI1: 伊朗 | AJ1: 意大利 | AK1: 印度 | AL1: 印尼 | AM1: 英国 | AN1: 越南 | AO1: 中国台湾 | AP1: 中国香港
A2: 8 | B2: 1 | C2: 3 | D2: 25 | E2: 4 | F2: 1 | G2: 5 | H2: 7 | I2: 1 | J2: 8 | K2: 13 | L2: 9 | M2: 2 | N2: 3 | O2: 4 | P2: 3 | Q2: 20 | R2: 7 | S2: 11 | T2: 2 | U2: 1 | V2: 1 | W2: 3 | X2: 15 | Y2: 2 | Z2: 1 | AA2: 1 | AB2: 25 | AC2: 4 | AD2: 9 | AE2: 6 | AF2: 1 | AG2: 7 | AH2: 1 | AI2: 1 | AJ2: 4 | AK2: 2 | AL2: 6 | AM2: 11 | AN2: 9 | AO2: 1 | AP2: 25

Sheet Sheet22
A1: 中国香港 | B1: 25
A2: 日本 | B2: 25
A3: 澳大利亚 | B3: 25
A4: 韩国 | B4: 20
A5: 马来西亚 | B5: 15
A6: 俄罗斯 | B6: 13
A7: 英国 | B7: 11
A8: 加拿大 | B8: 11
A9: 越南 | B9: 9
A10: 泰国 | B10: 9
A11: 法国 | B11: 9
A12: 德国 | B12: 8
... A42: 爱沙尼亚 | B42: 1

Sheet Sheet19
A1: 国家 | B1: 记录数
A2: 日本 | B2: 326
A3: 法国 | B3: 236
A4: 韩国 | B4: 170
A5: 英国 | B5: 145
A6: 澳大利亚 | B6: 138
A7: 印度 | B7: 133
A8: 中国香港 | B8: 125
A9: 阿联酋 | B9: 121
A10: 瑞典 | B10: 105
A11: 芬兰 | B11: 101
A12: 泰国 | B12: 99
A13: 加拿大 | B13: 93
... A51: 孟加拉 | B51: 3

Sheet Sheet3
B1: 2021AIP数据总计.xls 兼容性报表
B2: 运行时间: 2022/1/25 14:06
B4: 如果工作簿以早期的文件格式保存或在早期版本的 Microsoft Excel 中打开，将无法使用下列功能。
B6: 轻微保真损失 | E6: 发生次数 | F6: 版本
B8: 筛选此工作簿中的某些数据时使用了两个以上条件。在早期版本的 Excel 中，根据该筛选隐藏的行将保持为隐藏，但筛选本身将无法正常显示。 | E8: 1
E9: Sheet1'!A1:Z3097 | F9: Excel 97-2003
B11: 所选文件格式不支持此工作簿中某些单元格或样式包含的格式。这些格式将被转换为最相近的可用格式。 | E11: 8 | F11: Excel 97-2003
